<?xml version="1.0"?>
<robot name="wheeled_robin_hardware" xmlns:xacro="http://ros.org/wiki/xacro">

  <!-- Macro for WheeledRobin body. Including Gazebo extensions, but does not include Kinect -->
  <!-- <xacro:include filename="$(find wheeled_robin_description)/urdf/wheeled_robin_gazebo.urdf.xacro"/> -->

  <property name="base_x" value="0.33" />
  <property name="base_y" value="0.33" />

	<xacro:macro name="wheeled_robin">
	  <material name="Green">
	      <color rgba="0.0 0.8 0.0 1.0"/>
	  </material>
	
	  <!-- base_footprint is a fictitious link(frame) that is on the ground right below base_link origin, navigation stack depends on this frame -->
	  <link name="base_footprint">
	    <!--<visual>
	      <origin xyz="0 0 0" rpy="0 0 0" />
	      <geometry>
	        <box size="0.001 0.001 0.001" />
	      </geometry>
	      <material name="Green" />
	    </visual>
	
	    <collision>
	      <origin xyz="0 0 0.017" rpy="0 0 0" />
	      <geometry>
	       <box size="0.001 0.001 0.001" />
	      </geometry>
	    </collision>-->
	  </link>
	
	  <link name="base_link">
	    <!--<inertial>
	      <mass value="2" />
	      <origin xyz="0 0 0.0" />
	      <inertia ixx="0.01" ixy="0.0" ixz="0.0"
	        iyy="0.01" iyz="0.0" izz="0.5" />
	    </inertial> -->
	
	    <visual>
	      <origin xyz=" 0 0 0.07" rpy="0 0 0" />
	      <geometry>
	        <box size="0.124 0.19 0.2" />
	      </geometry>
	    </visual>
	
	    <!--<collision>
	      <origin xyz="0.0 0.0 0.0308" rpy="0 0 0" />
	      <geometry>
	        <cylinder length="0.0611632" radius="0.016495"/>
	      </geometry>
	    </collision>-->
	  </link>
	
	  <joint name="base_footprint_joint" type="fixed">
	    <origin xyz="0 0 0.055" rpy="0 0 0" />        
	    <parent link="base_footprint"/>
	    <child link="base_link" />
	  </joint>
	
	  <link name="left_wheel_link">
	    <!--<inertial>
	      <origin xyz="0 0 0"/>
	      <mass value="0.01" />
	      <inertia ixx="0.001" ixy="0.0" ixz="0.0"
	        iyy="0.001" iyz="0.0" izz="0.001" />
	    </inertial> -->
	
	    <visual>
	      <origin xyz="0 0 0" rpy="0 1.5707 1.5707" />
	      <geometry>
	        <cylinder radius="0.055" length = "0.05"/>
	      </geometry>
	      <material name="Green" />
	    </visual>
	
	    <!--<collision>
	      <origin xyz="0 0 0" rpy="0 1.5707 1.5707" />
	      <geometry>
	        <cylinder radius="0.033" length = "0.023"/>
	      </geometry>
	    </collision> -->
	  </link>
	
	  <joint name="left_wheel_joint" type="continuous">
	    <origin xyz="0 0.118 0" rpy="0 0 0"/>
	    <parent link="base_link"/>
	    <child link="left_wheel_link"/>
	    <axis xyz="0 1 0"/>
	  </joint>
	
	  <link name="right_wheel_link">
	    <!--<inertial>
	      <origin xyz="0 0 0"/>
	      <mass value="0.01" />
	      <inertia ixx="0.001" ixy="0.0" ixz="0.0"
	        iyy="0.001" iyz="0.0" izz="0.001" />
	    </inertial> -->
	
	    <visual>
	      <origin xyz="0 0 0" rpy="0 1.5707 1.5707" />
	      <geometry>
	        <mesh filename="package://wheeled_robin_description/meshes/reifenascii.stl"/>-->
	        <!--<cylinder radius="0.055" length = "0.05"/>-->
	      </geometry>
	      <material name="Green" />
	    </visual>
	
	    <!--<collision>
	      <origin xyz="0 0 0" rpy="0 1.5707 1.5707" />
	      <geometry>
	        <cylinder radius="0.033" length = "0.023"/>
	      </geometry>
	    </collision> -->
	  </link>
	
	  <joint name="right_wheel_joint" type="continuous">
	    <origin xyz="0 -0.118 0" rpy="0 0 0"/>
	    <parent link="base_link"/>
	    <child link="right_wheel_link"/>
	    <axis xyz="0 1 0"/>
	  </joint>
	
	  <!--<link name="gyro_link">
	    <inertial>
	      <mass value="0.001" />
	      <origin xyz="0 0 0" rpy="0 0 0" />
	      <inertia ixx="0.0001" ixy="0" ixz="0" iyy="0.000001" iyz="0" izz="0.0001" />
	    </inertial>
	  </link>
	  
	  <joint name="gyro_joint" type="fixed">
	    <axis xyz="0 1 0" />
	    <origin xyz="0 0 0.04" rpy="0 0 0" />
	    <parent link="base_link"/>
	    <child link="gyro_link"/>
	  </joint>-->

	  <link name="laser">
	    <!--<visual>
	      <geometry>
	        <box size="0 0 0.5" />
	      </geometry>
	      <material name="Green" />
	    </visual>
	    <inertial>
	      <mass value="0.001" />
	      <origin xyz="0 0 0" />
	      <inertia ixx="0.0001" ixy="0.0" ixz="0.0"
	        iyy="0.0001" iyz="0.0"
	        izz="0.0001" />
	    </inertial>-->
	  </link>
	  
	  <joint name="laser_joint" type="fixed">
	    <origin xyz="-0.065 0 0.075" rpy="0 0 0" />
	    <parent link="base_link" />
	    <child link="laser" />
	  </joint>
	  
	  <!-- Simulation sensors -->
	  <!--<sim_wheeled_robin/>
	  <sim_wheeled_robin_wall_sensor/>
	  <sim_wheeled_robin_cliff_sensors/>
	  <sim_imu/>-->
	</xacro:macro>
</robot>
